<mujoco model="slidecabinet">
    <compiler inertiafromgeom="auto" inertiagrouprange="1 4" angle="radian"/>

    <asset>
        <texture name="T_slide_metal" type="cube" height="1" width="1" file="common/textures/metal0.png"/>
        <texture name="T_slide_wood" type="cube" height="1" width="1" file="common/textures/wood1.png"/>

        <material name="M_slide_metal" texture="T_slide_metal" texrepeat="3 3" reflectance="0.7" shininess=".4" texuniform="false"/>
        <material name="M_slide_blue" texture="T_slide_wood" rgba="1 1 1 1" reflectance="0.7" shininess=".4" texuniform="false"/>
        <material name="slide_collision_blue" rgba="0.3 0.3 1.0 0.5" shininess="0" specular="0"/>
    </asset>
    <default>
        <default class="slidecabinet">
            <joint damping="2" frictionloss="2" armature=".01" limited="true"/>
            <geom conaffinity="0" contype="0" group="1" material="M_slide_blue" type="mesh"/>
            <default class="slide_collision">
                <geom conaffinity="1" condim="3" contype="0" group="4" margin="0.001" material="slide_collision_blue"/>
            </default>
        </default>
    </default>

    <sensor>
        <jointpos name="slidedoor_joint" joint="slidedoor_joint"/>
    </sensor>

    <worldbody>
        <body name="slide" childclass="slidecabinet" pos="0 0 .25">
            <geom pos="-0.225 0 -0.18" size="0.223 0.3 0.02" type="box"/>
            <geom pos="0.224 0 0" size="0.226 0.3 0.2" type="box"/>
            <geom pos="-0.225 0 0.18" size="0.223 0.3 0.02" type="box"/>
            <geom pos="-0.426 0 0" size="0.022 0.3 0.16" type="box"/>
            <geom pos="-0.2 0.276 0.0" size="0.21 0.024 0.16" type="box"/>

            <geom class="slide_collision" pos="-0.225 0 -0.18" size="0.223 0.3 0.02" type="box" mass=".2"/>
            <geom class="slide_collision" pos="0.224 0 0" size="0.226 0.3 0.2" type="box" mass="1"/>
            <geom class="slide_collision" pos="-0.225 0 0.18" size="0.223 0.3 0.02" type="box" mass=".2"/>
            <geom class="slide_collision" pos="-0.426 0 0" size="0.022 0.3 0.16" type="box" mass=".2"/>
            <geom class="slide_collision" pos="-0.2 0.276 0" size="0.2 0.024 0.16" type="box" mass=".2"/>
            <body name="slidelink" pos="-0.225 -0.32 0">
                <joint name="slidedoor_joint" axis="1 0 0" type="slide" range="0 .44"/>
                <geom material="M_slide_metal" euler="1.57 0 0" pos="-0.183 -0.06 -0.114" size="0.019 0.053 0.019" type="cylinder"/>
                <geom material="M_slide_metal" euler="1.57 0 0" pos="-0.183 -0.06 0.114" size="0.019 0.053 0.019" type="cylinder"/>
                <geom material="M_slide_metal" pos="-0.183 -0.123 0" size="0.022 0.159" type="cylinder"/>
                <geom pos="0 -.02 0" size="0.225 0.03 0.195" type="box"/>

                <geom class="slide_collision" pos="0 -.02 0" size="0.225 0.03 0.195" type="box" mass=".2"/>
                <geom class="slide_collision" euler="1.57 0 0" pos="-0.183 -0.06 -0.114" size="0.019 0.053 0.019" type="cylinder" mass=".02"/>
                <geom class="slide_collision" euler="1.57 0 0" pos="-0.183 -0.06 0.114" size="0.019 0.053 0.019" type="cylinder" mass=".02"/>
                <geom class="slide_collision" pos="-0.183 -0.123 0" size="0.022 0.159" type="cylinder" mass=".1"/>
                <site type="sphere" name="slide_site" pos="-0.183 -0.123 0" size=".01" group="3"/>
            </body>
        </body>

    </worldbody>

</mujoco>
