<mujoco model="box cabinet">

    <compiler inertiafromgeom="auto" inertiagrouprange="1 4" angle="radian"/>

    <asset>
        <texture name="T_hinge_wood" type="cube" height="1" width="1" file="common/textures/wood1.png"/>
        <texture name="T_hinge_metal" type="cube" height="1" width="1" file="common/textures/metal0.png"/>

        <material name="M_hinge_wood" texture="T_hinge_wood" texrepeat="3 3" reflectance="0.7" shininess=".4" texuniform="false"/>
        <material name="M_hinge_metal" texture="T_hinge_metal" texrepeat="3 3" reflectance="0.7" shininess=".4" texuniform="false"/>
        <material name="M_hinge_blue" texture="T_hinge_wood" rgba="1 1 1 1" reflectance="0.7" shininess=".4" texuniform="false"/>
        <material name="hinge_collision_blue" rgba="0.3 0.3 1.0 0.5" shininess="0" specular="0"/>
    </asset>

    <default>
        <default class="boxcabinet">
            <joint damping="2" frictionloss="2" armature=".01" limited="true"/>
            <geom conaffinity="0" contype="0" group="1" material="M_hinge_wood" type="mesh"/>
            <default class="box_collision">
                <geom conaffinity="1" condim="3" contype="0" group="4" margin="0.001" material="hinge_collision_blue" solimp=".8 .9 .01" solref=".02 1"/>
            </default>
        </default>
    </default>

    <actuator>
        <position joint="boxdoorhinge" ctrlrange="-3.14 3.14" name="boxdoorhinge_j" ctrllimited="true" kp="100"/>
    </actuator>

    <sensor>
        <jointpos name="boxdoorhinge" joint="boxdoorhinge"/>
    </sensor>

    <worldbody>
        <body name="hingecab" childclass="boxcabinet" pos="0. 0 0.2">
            <geom material="M_hinge_blue" pos="0.18 0 0" size="0.02 0.3 0.2" type="box"/>
            <geom material="M_hinge_blue" pos="-.18 0 0" size="0.02 0.3 0.2" type="box"/>
            <geom material="M_hinge_blue" pos="0.00 0 0.18" size="0.16 0.3 0.02" type="box"/>
            <geom material="M_hinge_blue" pos="0.00 0 -0.18" size="0.16 0.3 0.02" type="box"/>
            <geom material="M_hinge_blue" pos="0.00 0.28 0" size="0.16 0.02 0.16" type="box"/>

            <geom class="box_collision" pos="0.18 0 0" size="0.02 0.3 0.2" type="box" mass=".3"/>
            <geom class="box_collision" pos="-.18 0 0" size="0.02 0.3 0.2" type="box" mass=".2"/>
            <geom class="box_collision" pos="0.00 0 0.18" size="0.16 0.3 0.02" type="box" mass=".2"/>
            <geom class="box_collision" pos="0.00 0 -0.18" size="0.16 0.3 0.02" type="box" mass=".2"/>
            <geom class="box_collision" pos="0.00 0.28 0" size="0.16 0.02 0.16" type="box" mass=".2"/>

            <body name="hingedoor" pos="-0.18 -0.32 0">
                <joint axis="0 0 1" name="boxdoorhinge" range="-1.57 0"/>
                <geom material="M_hinge_metal" pos="0.302 -0.128 0" size="0.022 0.16" type="cylinder"/>
                <geom material="M_hinge_metal" pos="0.302 -0.061 0.114" euler="1.57 0 0" size="0.019 0.053 0.02" type="cylinder"/>
                <geom material="M_hinge_metal" pos="0.302 -0.061 -0.114" euler="1.57 0 0" size="0.019 0.053 0.02" type="cylinder"/>
                <geom material="M_hinge_blue" pos="0.184 -.015 0" size="0.193 0.03 0.2" type="box"/>

                <geom class="box_collision" pos="0.184 -.015 0" size="0.193 0.03 0.2" type="box" mass=".2"/>
                <geom class="box_collision" pos="0.302 -0.128 0" size="0.022 0.16" type="cylinder" mass=".1"/>
                <geom class="box_collision" pos="0.302 -0.061 0.114" euler="1.57 0 0" size="0.019 0.053 0.02" type="cylinder" mass=".02"/>
                <geom class="box_collision" pos="0.302 -0.061 -0.114" euler="1.57 0 0" size="0.019 0.053 0.02" type="cylinder" mass=".02"/>
                <site type="sphere" name="boxdoor_site" pos="0.302 -0.128 0" size=".01" group="3" rgba="1 0 0 1"/>
            </body>
        </body>
    </worldbody>

</mujoco>