<mujoco model="lightButtons">
    <compiler angle="radian" meshdir="" texturedir=""/>
    <asset>
        <mesh name="ButtonHolder" file="lightButtons/meshes/ButtonHolder.stl" scale="0.01 0.01 0.01" />
        <mesh name="lightsHolder" file="lightButtons/meshes/ButtonHolder.stl" scale="0.02 0.01 0.02" />
        <texture name="T_Metal_lightButton" type="cube" height="1" width="1" file="common/textures/metal0.png" />
        <material name="M_Metal_lightButton" texture="T_Metal_lightButton" texrepeat="3 3" reflectance="0.7" texuniform="false" />
	</asset>

    <equality>
        <joint joint1='red button' joint2='red light' polycoef='0 1 0 0 0'/>
        <joint joint1='blue button' joint2='blue light' polycoef='0 1 0 0 0'/>
        <joint joint1='green button' joint2='green light' polycoef='0 1 0 0 0'/>
    </equality>

    <default>
        <default class="class_button_col" >
            <geom contype="1" conaffinity="1" rgba="0.8 0.9 0.7 1.0" group='4'/>
            <joint limited="true" damping="0" stiffness="0" range="-0.005 0" />
        </default>

        <default class="viz_holder" >
            <geom contype="0" conaffinity="0" group="1" material='M_Metal_lightButton'/>
        </default>

        <default class="class_lights_viz" >
            <geom contype="0" conaffinity="0" group="1" />
            <joint limited="true" damping="0" stiffness="0" range="-0.005 0" />
        </default>

         <default class="class_lights_col" >
            <geom contype="1" conaffinity="1" rgba="0.8 0.9 0.7 1.0" group='4'/>
        </default>
   </default>

    <worldbody>
        <body name="red light" pos="0.0 0.15 0.01" childclass="class_lights_viz" >
            <geom type="mesh" mesh="lightsHolder" euler="-1.57 0 3.14"/>
            <geom type="cylinder" size=".06 .001" pos="0 0 .011" rgba="0 0 0 1.0" group="1" contype="0" conaffinity="0" />
            <geom type="cylinder" size=".08 .02" pos="0 0 .011" class='class_lights_col'/>

            <body>
                <geom type="cylinder" size=".06 .0075" rgba=".4 .5 .6 1" group="3" mass="0.01" />
                <geom type="cylinder" size=".06 .0075" rgba="1 0 0 .4" group="1" mass="0.01" />
                <joint name="red light" type="slide" axis="0 0 -1" />
            </body>
        </body>

        <!-- <body name="green light" pos="0 .15 0" childclass="class_lights_viz" >
            <geom type="mesh" mesh="lightsHolder" euler="-1.57 0 3.14"/>
            <geom type="cylinder" size=".06 .001" pos="0 0 .011" rgba="0 0 0 1.0" group="1" contype="0" conaffinity="0" />
            <geom type="cylinder" size=".08 .02" pos="0 0 .011" class='class_lights_col'/>

            <body>
                <geom type="cylinder" size=".06 .0075" rgba=".4 .5 .6 1" group="3" mass="0.01" />
                <geom type="cylinder" size=".06 .0075" rgba="0 1 0 .4" group="1" mass="0.01" />
                <joint name="green light" type="slide" axis="0 0 -1" />
            </body>
        </body>

        <body name="blue light" pos=".2 .15 0" childclass="class_lights_viz" >
            <geom type="mesh" mesh="lightsHolder" euler="-1.57 0 3.14"/>
            <geom type="cylinder" size=".06 .001" pos="0 0 .011" rgba="0 0 0 1.0" group="1" contype="0" conaffinity="0" />
            <geom type="cylinder" size=".08 .02" pos="0 0 .011" class='class_lights_col'/>

            <body>
                <geom type="cylinder" size=".06 .0075" rgba=".4 .5 .6 1" group="3" mass="0.01" />
                <geom type="cylinder" size=".06 .0075" rgba="0 0 1 .4" group="1" mass="0.01" />
                <joint name="blue light" type="slide" axis="0 0 -1" />
            </body>
        </body> -->

        <body name="red button" pos="0.0 0 0.01" childclass='class_button_col'>
            <geom class="viz_holder" type="mesh" mesh="ButtonHolder" euler="-1.57 0 3.14"/>
            <geom type="box" size=".002 .015 .015" pos="0.035 0 .015" />
            <geom type="box" size=".002 .015 .015" pos="-0.035 0 .015" />
            <geom type="box" size=".002 .015 .015" pos="0 0.035 .015" euler="0 0 1.57" />
            <geom type="box" size=".002 .015 .015" pos="0 -0.035 .015" rgba="0.8 0.9 0.7 1.0" euler="0 0 1.57" />
            <geom type="box" size=".002 .015 .015" pos="0.025 0.025 .015" euler="0 0 0.785" />
            <geom type="box" size=".002 .015 .015" pos="-0.025 0.025 .015" rgba="0.8 0.9 0.7 1.0" euler="0 0 -.785" />
            <geom type="box" size=".002 .015 .015" pos="0.025 -0.025 .015" euler="0 0 -0.785" />
            <geom type="box" size=".002 .015 .015" pos="-0.025 -0.025 .015" rgba="0.8 0.9 0.7 1.0" euler="0 0 .785" />
            <geom type="box" size=".02 .02 .002" pos="0 0 0" />
            <body >
                <geom type="cylinder" size=".03 .01" pos='0 0 .02' class='class_button_col' mass="0.01" />
                <geom type="cylinder" size=".03 .01" pos='0 0 .02' rgba="0.3 0 0 1.0" class="viz_holder"/>
                <joint name="red button" type="slide" pos="0 0 0" axis="0 0 1" damping="1" stiffness="10" />
            </body>
        </body>


        <!-- <body name="green button" pos="0 0 0" childclass='class_button_col'>
            <geom class="viz_holder" type="mesh" mesh="ButtonHolder" euler="-1.57 0 3.14"/>
            <geom type="box" size=".002 .015 .015" pos="0.035 0 .015" />
            <geom type="box" size=".002 .015 .015" pos="-0.035 0 .015" />
            <geom type="box" size=".002 .015 .015" pos="0 0.035 .015" euler="0 0 1.57" />
            <geom type="box" size=".002 .015 .015" pos="0 -0.035 .015" rgba="0.8 0.9 0.7 1.0" euler="0 0 1.57" />
            <geom type="box" size=".002 .015 .015" pos="0.025 0.025 .015" euler="0 0 0.785" />
            <geom type="box" size=".002 .015 .015" pos="-0.025 0.025 .015" rgba="0.8 0.9 0.7 1.0" euler="0 0 -.785" />
            <geom type="box" size=".002 .015 .015" pos="0.025 -0.025 .015" euler="0 0 -0.785" />
            <geom type="box" size=".002 .015 .015" pos="-0.025 -0.025 .015" rgba="0.8 0.9 0.7 1.0" euler="0 0 .785" />
            <geom type="box" size=".02 .02 .002" pos="0 0 0" />
            <body >
                <geom type="cylinder"  size=".03 .01" pos='0 0 .02' class='class_button_col' mass="0.01" />
                <geom type="cylinder"  size=".03 .01" pos='0 0 .02' rgba="0 0.3 0 1.0" class="viz_holder"/>
                <joint name="green button" type="slide" pos="0 0 0" axis="0 0 1" damping="1" stiffness="10" />
            </body>
        </body>


        <body name="blue button" pos="0.2 0 0" childclass='class_button_col'>
            <geom class="viz_holder" type="mesh" mesh="ButtonHolder" euler="-1.57 0 3.14" />
            <geom type="box" size=".002 .015 .015" pos="0.035 0 .015" />
            <geom type="box" size=".002 .015 .015" pos="-0.035 0 .015" />
            <geom type="box" size=".002 .015 .015" pos="0 0.035 .015" euler="0 0 1.57" />
            <geom type="box" size=".002 .015 .015" pos="0 -0.035 .015" rgba="0.8 0.9 0.7 1.0" euler="0 0 1.57" />
            <geom type="box" size=".002 .015 .015" pos="0.025 0.025 .015" euler="0 0 0.785" />
            <geom type="box" size=".002 .015 .015" pos="-0.025 0.025 .015" rgba="0.8 0.9 0.7 1.0" euler="0 0 -.785" />
            <geom type="box" size=".002 .015 .015" pos="0.025 -0.025 .015" euler="0 0 -0.785" />
            <geom type="box" size=".002 .015 .015" pos="-0.025 -0.025 .015" rgba="0.8 0.9 0.7 1.0" euler="0 0 .785" />
            <geom type="box" size=".02 .02 .002" pos="0 0 0" />
            <body >
                <geom type="cylinder"  size=".03 .01" pos='0 0 .02' class='class_button_col' mass="0.01" />
                <geom type="cylinder"  size=".03 .01" pos='0 0 .02' rgba="0 0 0.3 1.0" class="viz_holder"/>
                <joint name="blue button" type="slide" pos="0 0 0" axis="0 0 1" damping="1" stiffness="10" />
            </body>
        </body> -->
    </worldbody>

</mujoco>